Workbook
Name ACQ: Допущения!$C$68
Name AGENCY_FEE: Допущения!$C$10
Name CAC_DIRECT: Допущения!$C$67
Name CASUAL_ACT: Допущения!$C$40
Name CASUAL_SH: Допущения!$C$31
Name CHATS_PER_EMP: Допущения!$C$54
Name CHURN: Допущения!$C$64
Name COST_TRIAL_MKT: Допущения!$C$66
Name CPH_MKT: Допущения!$C$11
Name CPH_PLATFORM: Допущения!$C$12
Name DIRECT_NEW: Допущения!$C$63
Name FINE: Допущения!$C$25
Name FINE_SHARE: Допущения!$C$26
Name HABR_VAC: Допущения!$C$18
Name HH_DB: Допущения!$C$17
Name HH_VAC: Допущения!$C$19
Name HR_HRS: Допущения!$C$14
Name HR_HRS_COMIT: Допущения!$C$16
Name HR_RATE: Допущения!$C$15
Name INFRA_FIX: Допущения!$C$56
Name INFRA_PER_EMP: Допущения!$C$57
Name INV_PER_EMP_BIZ: Допущения!$C$39
Name INV_PER_EMP_CAS: Допущения!$C$35
Name INV_PER_EMP_SUB: Допущения!$C$38
Name INV_PER_HIRE: Допущения!$C$33
Name INV_PRICE: Допущения!$C$24
Name LLM_BUF: Допущения!$C$55
Name LLM_CHAT: Допущения!$C$53
Name LLM_IN: Допущения!$C$42
Name LLM_INV: Допущения!$C$52
Name LLM_OUT: Допущения!$C$43
Name LLM_VAC: Допущения!$C$51
Name OPEX_OTHER: Допущения!$C$73
Name PAYROLL_EARLY: Допущения!$C$71
Name PAYROLL_LATE: Допущения!$C$72
Name SAL_JUN: Допущения!$C$7
Name SAL_MEDIAN: Допущения!$C$6
Name SAL_MID: Допущения!$C$8
Name SAL_SEN: Допущения!$C$9
Name SUB_BIZ: Допущения!$C$28
Name SUB_BIZ_SH: Допущения!$C$30
Name SUB_START: Допущения!$C$27
Name SUB_START_SH: Допущения!$C$29
Name SUPPORT_TRIAL: Допущения!$C$69
Name TOK_CHAT_IN: Допущения!$C$49
Name TOK_CHAT_OUT: Допущения!$C$50
Name TOK_INV_IN: Допущения!$C$47
Name TOK_INV_OUT: Допущения!$C$48
Name TOK_VAC_IN: Допущения!$C$45
Name TOK_VAC_OUT: Допущения!$C$46
Name TRIAL_CAP: Допущения!$C$61
Name TRIAL_CONV: Допущения!$C$62
Name TRIAL_GR: Допущения!$C$60
Name TRIALS_M1: Допущения!$C$59
Name TTH_MKT: Допущения!$C$13
Name USD: Допущения!$C$44
Name VAC_AVG: Допущения!$C$23
Name VAC_FIRST: Допущения!$C$21
Name VAC_NEXT: Допущения!$C$22
Name VAC_PER_EMP: Допущения!$C$34

Sheet Резюме
B2: COMIT — экономическая модель: резюме
B3: Платформа подбора IT-специалистов с обратной механикой (ЛЦТ 2026, спецтрек ФСП). Все цифры — живые формулы; входные параметры на листе «Допущения».
B5: ='Затраты работодателя'!F5 -> 4081 | D5: ='Затраты работодателя'!F10 -> 548100 | F5: ='Затраты работодателя'!G14 -> 0.99255428 | H5: =Выручка!Z8 -> 1021.5552
B6: Стоимость найма через COMIT | D6: Полная стоимость найма на рынке | F6: Экономия работодателя | H6: Платящих на мес 24
B9: =Выручка!Z18*12 -> 65979210 | D9: =Безубыточность!C8 -> 15 | F9: ='Юнит-экономика'!C16 -> 12.324371 | H9: ='Юнит-экономика'!C11 -> 0.95621561
B10: ARR к месяцу 24 | D10: Месяц выхода EBITDA в плюс | F10: LTV / CAC | H10: Валовая маржа
B13: Выводы
B14: 1. Ценность для работодателя: один найм через COMIT стоит ≈ 4,1 тыс ₽ против ≈ 448 тыс ₽ через агентство и ≈ 548 тыс ₽ полной рыночной стоимости найма (25–30% годовой ЗП) — экономия > 99%. Основной эффект: готовая проверенная подборка вместо сотен откликов и 80 часов HR.
B15: 2. Монетизация: тариф 199 ₽/499 ₽ за вакансию и 49 ₽ за приглашение ниже конкурентов (hh ~800 ₽/вакансия, база 22 080 ₽/нед, Хабр 4 026 ₽/вакансия) — вход без барьера; рост выручки за счёт подписок «Старт»/«Бизнес» (ARPU 5,4 тыс ₽/мес).
B16: 3. Экономика: LTV/CAC ≈ 12× при окупаемости CAC за ~1,6 мес; безубыточность на 15-м месяце при 237+ платящих; к месяцу 24 — 1 022 платящих и ARR ≈ 66 млн ₽ (0,16% выручки hh.ru).
B17: 4. Триал 14 дней (1 вакансия + 10 приглашений, без карты) стоит COMIT ≈ 270 ₽ и даёт работодателю ценность ≈ 9 тыс ₽ — конверсия 25% даёт CAC ≈ 9,1 тыс ₽.
B18: 5. Себестоимость LLM на работодателя — копейки (DeepSeek $0.2/$0.7 за 1M токенов): валовая маржа ≈ 96%; ключевые затраты — команда и маркетинг.
K20: Структура выручки, месяц 24 (данные графика):
K21: Канал | L21: Выручка, ₽
K22: Подписки «Старт» | L22: 2528349
K23: Подписки «Бизнес» | L23: 2443560
K24: Разовые (вакансии+приглашения) | L24: 511894
K25: Штрафы SLA | L25: 14464

Sheet Допущения
B2: Допущения модели — все входные параметры
B4: Параметр | C4: Значение | D4: Ед. изм. | E4: Источник / комментарий
B5: 1. Рынок труда (бенчмарки из открытых источников)
B6: Медианная ЗП IT-специалиста | C6: 182700 | D6: ₽/мес | E6: Хабр Карьера, 1П2025 (career.habr.com)
B7: ЗП Junior-разработчика | C7: 77000 | D7: ₽/мес | E7: Skillbox, авг 2025
B8: ЗП Middle-разработчика | C8: 167000 | D8: ₽/мес | E8: Skillbox, авг 2025
B9: ЗП Senior-разработчика | C9: 280000 | D9: ₽/мес | E9: Skillbox, авг 2025
B10: Комиссия IT-агентств (средняя) | C10: 0.2 | D10: % год. дохода | E10: IT-Atlas 10–25%, Lucky Hunter 19–23%, скрин: 15–25%
B11: Полный cost-per-hire на рынке | C11: 0.25 | D11: % годовой ЗП | E11: скрин пользователя: 25–30% годовой зарплаты
B12: Cost-per-hire площадок (нижняя граница) | C12: 43000 | D12: ₽ | E12: vc.ru: полный CPH > 43 000 ₽ на закрытую вакансию
B13: Время найма IT-специалиста (рынок) | C13: 1.75 | D13: мес | E13: скрин пользователя: 1,5–2 месяца
B14: Часы HR на один найм (рынок) | C14: 80 | D14: ч | E14: скрин пользователя: десятки—110+ часов
B15: Стоимость часа рекрутера | C15: 1000 | D15: ₽/ч | E15: рекрутер ~120–150 тыс ₽/мес gross + взносы ~30%
B16: Часы HR на найм через COMIT | C16: 3 | D16: ч | E16: разбор готовой подборки вместо сотен резюме
B17: Доступ к базе резюме hh.ru (7 дней, Москва) | C17: 22080 | D17: ₽ | E17: heaad.ru, 2025
... B19: Вакансия hh.ru (пакетная, средняя) | C19: 800 | D19: ₽ | E19: jcat.ru: 6 200 ₽ за 10 размещений
B20: 2. Тарифы COMIT (ключевые редактируемые параметры)
B21: Вакансия — первая (акция) | C21: 199 | D21: ₽ | E21: стартовая ставка из репозитория; аналог промо hh «Вакансия за 199 ₽»
B22: Вакансия — повторная | C22: 499 | D22: ₽ | E22: ниже пакета hh (~800 ₽) и Хабра (4 026 ₽)
B23: Средняя цена вакансии (микс) | C23: =0.2*C21+0.8*C22 -> 439 | D23: ₽ | E23: 20% первых / 80% повторных
B24: Приглашение кандидату | C24: 49 | D24: ₽ | E24: стартовая ставка из репозитория
B25: Штраф за просрочку обратной связи | C25: 199 | D25: ₽ | E25: SLA-механика продукта (199 ₽)
B26: Доля вакансий с просрочкой | C26: 0.05 | D26: % | E26: консервативная оценка действия SLA
B27: Подписка «Старт», месяц | C27: 9900 | D27: ₽ | E27: 10 вакансий + 200 приглашений + ИИ до 1 000 ₽
B28: Подписка «Бизнес», месяц | C28: 29900 | D28: ₽ | E28: вакансии без лимита + 1 000 приглашений + ИИ до 5 000 ₽
B29: Доля «Старт» среди платящих | C29: 0.25 | D29: % | E29: целевой микс базы
B30: Доля «Бизнес» среди платящих | C30: 0.08 | D30: % | E30: целевой микс базы
B31: Доля разовых (без подписки) | C31: =1-C29-C30 -> 0.67 | D31: % | E31: остаток базы
B32: 3. Воронка найма через COMIT
B33: Приглашений на один закрытый найм | C33: 18 | D33: шт | E33: обратная механика: точечные приглашения с ЗП
B34: Вакансий на активного разового, мес | C34: 1.5 | D34: шт/мес | E34: средняя активность
B35: Приглашений на активного разового, мес | C35: 12 | D35: шт/мес | E35: средняя активность
B36: Вакансий на подписку «Старт», мес | C36: 2 | D36: шт/мес
B37: Вакансий на подписку «Бизнес», мес | C37: 4 | D37: шт/мес
B38: Приглашений на «Старт», мес | C38: 100 | D38: шт/мес
B39: Приглашений на «Бизнес», мес | C39: 300 | D39: шт/мес
B40: Активность разовых в месяц | C40: 0.6 | D40: % | E40: доля разовых, платящих в конкретном месяце
B41: 4. LLM и инфраструктура
B42: DeepSeek API: вход | C42: 0.2 | D42: $/1M токенов | E42: api-docs.deepseek.com; значения по умолчанию из репозитория
B43: DeepSeek API: выход | C43: 0.7 | D43: $/1M токенов | E43: api-docs.deepseek.com
...

Sheet Рынок
B2: Рынок: бенчмарки и конкуренты (открытые источники, окт 2026)
B4: Показатель | C4: Значение | D4: Ед. | E4: Источник | F4: Комментарий
B5: Зарплаты и рынок труда
B6: Медианная ЗП IT-специалиста, РФ | C6: 182 700 | D6: ₽/мес | E6: Хабр Карьера, 1П2025 | F6: фактическая медиана, +2% г/г
B7: Средняя ЗП в IT, РФ (3 кв 2025) | C7: 196 500 | D7: ₽/мес | E7: TAdviser / Росстат | F7: начисленная
B8: ЗП Junior / Middle / Senior | C8: 77 / 167 / 280 тыс | D8: ₽/мес | E8: Skillbox, авг 2025 | F8: по грейдам
B9: Активные резюме на hh.ru (июнь 2025) | C9: 3,24 млн | D9: шт | E9: hh.ru / stats.hh.ru | F9: +25% г/г — конкуренция кандидатов растёт
B10: IT-вакансии за 1П2025 | C10: 291 тыс | D10: шт | E10: proglib.io | F10: падение с 352,5 тыс (-17% г/г)
B11: hh-индекс IT (конкуренция) | C11: 22–26 | D11: резюме/вакансию | E11: stats.hh.ru (апр–авг 2026) | F11: порог высокой конкуренции — 12
B12: Стоимость найма (затраты работодателя)
B13: Полный cost-per-hire (все издержки) | C13: 25–30% годовой ЗП | D13: — | E13: скрин пользователя (междунар. бенчмарки) | F13: ≈ 548–658 тыс ₽ на IT-найм при медианной ЗП
B14: Cost-per-hire через площадки | C14: > 43 000 | D14: ₽ | E14: vc.ru | F14: нижняя граница прямых затрат
B15: Комиссия IT-рекрутингового агентства | C15: 10–25% годового дохода | D15: — | E15: IT-Atlas; Lucky Hunter 19–23%; скрин 15–25% | F15: ≈ 330–550 тыс ₽ за найм
B16: Время закрытия IT-вакансии | C16: 1,5–2 мес | D16: мес | E16: скрин пользователя; Т-Банк/Инфосистема Джет | F16: до 2 000 откликов на одну IT-вакансию
B17: Часы HR на один найм | C17: 40–110+ | D17: ч | E17: скрин пользователя | F17: просмотр, скрининг, интервью
B18: Тарифы площадок (конкуренты)
B19: hh.ru: промо «Вакансия за 199 ₽» | C19: 199 | D19: ₽ | E19: hh.ru (акция для новых клиентов) | F19: Стандарт Плюс, 1 шт, вкл. НДС
B20: hh.ru: пакет размещений | C20: ≈ 620–830 | D20: ₽/вакансия | E20: jcat.ru: 6 200 ₽ за 10 вакансий | F20: цены динамические, зависят от региона
B21: hh.ru: доступ к базе резюме (7 дней) | C21: 22 080 | D21: ₽ | E21: heaad.ru (Москва) | F21: по России — 27 670 ₽; до 8 000 просмотров/сут
B22: Хабр Карьера: вакансия «Стандарт», Москва | C22: 4 026 | D22: ₽/30 дн | E22: career.habr.com/price | F22: «Стандарт плюс» — 7 808 ₽
B23: Хабр Карьера: модель 2025 года | C23: 0 + 300 ₽/отклик | D23: ₽ | E23: habr.com/news, июнь 2025 | F23: бесплатное размещение для малого/среднего бизнеса
B24: Хабр Карьера: поднятие/выделение вакансии | C24: 1 220 | D24: ₽ | E24: career.habr.com/price | F24: разовые продвижения
B25: Рекрутер-фрилансер за подбор | C25: 10 000–20 000+ | D25: ₽ | E25: HRTime | F25: для сложных IT-позиций существенно дороже
B26: Рынок в целом
B27: Выручка hh.ru за 2025 | C27: 41,2 млрд | D27: ₽ | E27: TAdviser / Ведомости | F27: +4% г/г; чистая прибыль 18,18 млрд ₽
B28: Рынок рекрутмента РФ (оценка TAM) | C28: > 500 млрд | D28: ₽/год | E28: инвест. презентация HeadHunter | F28: вкл. HRtech
B29: LLM-затраты (для себестоимости COMIT)
B30: DeepSeek API: вход / выход | C30: $0.20 / $0.70 | D30: $/1M токенов | E30: api-docs.deepseek.com + репозиторий | F30: значения из .env агента проекта

Sheet Тарифы
B2: Тарифы COMIT — сетка и рыночные аналоги
B4: Тариф / услуга | C4: Цена | D4: Что входит | E4: Лимиты | F4: Рыночный аналог (цена)
B5: Триал «Первый найм» | C5: =0 -> 0 | D5: 1 вакансия, 10 приглашений, ИИ-черновик вакансии, категории + подобранные ленты, грейд-тесты кандидатов уже включены | E5: 14 дней, 1 триал на ИНН, без привязки карты | F5: промо hh «Вакансия за 199 ₽»; freemium Хабра (0 ₽ + 300 ₽/отклик)
B6: Разовый (pay-as-you-go) | C6: =VAC_FIRST -> 199 | D6: первая вакансия по акции; далее повторные | E6: без подписки, оплата по факту | F6: hh ~620–830 ₽/вакансия (пакет); повторная =VAC_NEXT ₽
B7: Подписка «Старт» | C7: =SUB_START -> 9900 | D7: 10 вакансий, 200 приглашений, ИИ-ассистент до 1 000 ₽/мес, статистика | E7: на месяц, автопродление | F7: доступ к базе hh 22 080 ₽ за 7 дней
B8: Подписка «Бизнес» | C8: =SUB_BIZ -> 29900 | D8: вакансии без лимита, 1 000 приглашений, ИИ до 5 000 ₽/мес, приоритетная поддержка, API | E8: на месяц, автопродление | F8: агентство: 20% годового дохода (≈ 438 тыс ₽/найм)
B9: Приглашение сверх лимита | C9: =INV_PRICE -> 49 | D9: точечное приглашение с ЗП | E9: — | F9: просмотр контакта из базы hh (в пакете доступа)
B10: Штраф за просрочку обратной связи | C10: =FINE -> 199 | D10: соц-механика SLA: обе стороны обязаны дать ОС | E10: 199 ₽ с виновной стороны | F10: уникальная механика COMIT — нет аналогов
B12: Цены — формулы со листа «Допущения» (меняются там). Кандидаты платят 0 ₽: монетизация только со стороны работодателя.

Sheet Затраты работодателя
B2: Затраты работодателя на один найм: каналы сравнения
B4: Канал найма | C4: Прямые затраты, ₽ | D4: Часы HR | E4: Стоимость HR-времени, ₽ | F4: ВСЕГО, ₽ | G4: Время найма, мес / экономия, % | H4: Комментарий | J4: Канал (данные графика) | K4: Всего, ₽
B5: COMIT — разовый тариф | C5: =VAC_FIRST+INV_PER_HIRE*INV_PRICE -> 1081 | D5: =HR_HRS_COMIT -> 3 | E5: =D5*HR_RATE -> 3000 | F5: =C5+E5 -> 4081 | G5: 0.75 | H5: акция 199 ₽ + 18 приглашений × 49 ₽; разбор готовой подборки | J5: COMIT разовый | K5: 4081
B6: COMIT — подписка «Старт» (на найм) | C6: =SUB_START/2 -> 4950 | D6: =HR_HRS_COMIT -> 3 | E6: =D6*HR_RATE -> 3000 | F6: =C6+E6 -> 7950 | G6: 0.75 | H6: 2 найма/мес у подписчика (лимит 200 приглашений ≈ 11 наймов) | J6: COMIT «Старт» | K6: 7950
B7: hh.ru самостоятельно | C7: =2*HH_VAC+HH_DB -> 23680 | D7: =HR_HRS -> 80 | E7: =D7*HR_RATE -> 80000 | F7: =C7+E7 -> 103680 | G7: =TTH_MKT -> 1.75 | H7: 2 вакансии + доступ к базе 7 дней; сотни откликов на вакансию | J7: hh.ru самост. | K7: 103680
B8: Хабр Карьера | C8: =HABR_VAC+1220 -> 5246 | D8: 70 | E8: =D8*HR_RATE -> 70000 | F8: =C8+E8 -> 75246 | G8: =TTH_MKT -> 1.75 | H8: вакансия «Стандарт» + выделение; 70 ч HR | J8: Хабр Карьера | K8: 75246
B9: IT-агентство | C9: =AGENCY_FEE*SAL_MEDIAN*12 -> 438480 | D9: 10 | E9: =D9*HR_RATE -> 10000 | F9: =C9+E9 -> 448480 | G9: 1.5 | H9: гонорар 20% годового дохода + курирование | J9: Агентство | K9: 448480
B10: Полная стоимость найма (рынок) | C10: =CPH_MKT*SAL_MEDIAN*12 -> 548100 | D10: 0 | E10: =D10*HR_RATE -> 0 | F10: =C10+E10 -> 548100 | G10: =TTH_MKT -> 1.75 | H10: 25–30% годовой ЗП: все издержки вкл. простой и онбординг | J10: Полная ст-ть найма | K10: 548100
B11: In-house рекрутер | C11: =169000*TTH_MKT -> 295750 | D11: 0 | E11: =D11*HR_RATE -> 0 | F11: =C11+E11 -> 295750 | G11: =TTH_MKT -> 1.75 | H11: 130 тыс ₽/мес × 1,3 (взносы) × 1,75 мес | J11: In-house рекрутер | K11: 295750
B13: Экономия: COMIT (разовый) против IT-агентства | F13: =F9-F5 -> 444399 | G13: =1-F5/F9 -> 0.99090037
B14: Экономия: COMIT (разовый) против полной рыночной стоимости найма | F14: =F10-F5 -> 544019 | G14: =1-F5/F10 -> 0.99255428
B16: Часы HR: COMIT — 3 ч (разбор готовой отранжированной подборки), рынок — 80 ч (скрин, сотни откликов). Стоимость часа — см. «Допущения».

Sheet Триал
B2: Триал для работодателя — дизайн и экономика
B4: Условия триала «Первый найм»
B5: Длительность | C5: 14 дней с момента активации
B6: Что входит | C6: 1 вакансия с ИИ-черновиком, 10 приглашений кандидатам с ЗП, полный доступ к категориям и подобранным лентам, грейд-тесты кандидатов уже пройдены
B7: Оплата | C7: 0 ₽, без привязки карты — демо ценности до платежа
B8: Ограничители | C8: 1 триал на ИНН (верификация юрлица), контакты кандидатов скрыты до принятия приглашения — как в продукте
B9: Окончание | C9: автоматический даунгрейд до просмотра; апселл: Разовый → «Старт» → «Бизнес»
B10: Почему именно так | C10: работодатель тратит 25–30% годовой ЗП на один найм (скрин): бесплатная проверка экономии сотен тысяч ₽ — сильный крючок
B12: Экономика триала
B13: Показатель | C13: Значение | D13: Как считаем
B14: Себестоимость триала для COMIT, ₽ | C14: =(LLM_VAC+10*LLM_INV+2*LLM_CHAT)*LLM_BUF+SUPPORT_TRIAL+INFRA_PER_EMP -> 267.26 | D14: LLM (1 вакансия + 10 приглашений + 2 чата, с запасом ×3) + поддержка + инфраструктура
B15: Ценность для работодателя (консервативно), ₽ | C15: =HABR_VAC+10*0.5*HR_RATE -> 9026 | D15: размещение вакансии по цене Хабра + скрининг 10 кандидатов (0,5 ч × ставка HR)
B16: Эквивалент: доступ к базе hh.ru на 7 дней, ₽ | C16: =HH_DB -> 22080 | D16: что пришлось бы купить для тех же 10 точечных контактов
B17: Конверсия триал → платящий | C17: =TRIAL_CONV -> 0.25 | D17: B2B SaaS freemium-бенчмарк 15–40%
B18: CAC через триал, ₽ | C18: =(COST_TRIAL_MKT+(LLM_VAC+10*LLM_INV+2*LLM_CHAT)*LLM_BUF+SUPPORT_TRIAL+INFRA_PER_EMP)/TRIAL_CONV -> 9069.04 | D18: (маркетинг на триал + себестоимость) / конверсия
B19: LTV платящего работодателя, ₽ | C19: ='Юнит-экономика'!C14 -> 102661.09 | D19: маржинальная прибыль × средняя жизнь
B20: LTV / CAC через триал | C20: ='Юнит-экономика'!C14/((COST_TRIAL_MKT+(LLM_VAC+10*LLM_INV+2*LLM_CHAT)*LLM_BUF+SUPPORT_TRIAL+INFRA_PER_EMP)/TRIAL_CONV) -> 11.319951 | D20: здоровая экономика: > 3×
B21: Затраты COMIT на 1 перешедшего, ₽ | C21: =(COST_TRIAL_MKT+(LLM_VAC+10*LLM_INV+2*LLM_CHAT)*LLM_BUF+SUPPORT_TRIAL+INFRA_PER_EMP)/TRIAL_CONV -> 9069.04 | D21: совпадает с CAC через триал

Sheet Выручка
B2: Выручка COMIT — помесячная модель, 24 месяца (базовый сценарий)
B4: Метрика | C4: 1 | D4: 2 | E4: 3 | F4: 4 | G4: 5 | H4: 6 | I4: 7 | J4: 8 | K4: 9 | L4: 10 | M4: 11 | N4: 12 | O4: 13 | P4: 14 | Q4: 15 | R4: 16 | S4: 17 | T4: 18 | U4: 19 | V4: 20 | W4: 21 | X4: 22 | Y4: 23 | Z4: 24 | AA4: Итого / финал
B5: Новые триалы | C5: =TRIALS_M1 -> 30 | D5: =MIN(TRIALS_M1*(1+TRIAL_GR)^(D$4-1),TRIAL_CAP) -> 34.5 | E5: =MIN(TRIALS_M1*(1+TRIAL_GR)^(E$4-1),TRIAL_CAP) -> 39.675 | F5: =MIN(TRIALS_M1*(1+TRIAL_GR)^(F$4-1),TRIAL_CAP) -> 45.62625 | G5: =MIN(TRIALS_M1*(1+TRIAL_GR)^(G$4-1),TRIAL_CAP) -> 52.470187 | H5: =MIN(TRIALS_M1*(1+TRIAL_GR)^(H$4-1),TRIAL_CAP) -> 60.340716 | I5: =MIN(TRIALS_M1*(1+TRIAL_GR)^(I$4-1),TRIAL_CAP) -> 69.391823 | J5: =MIN(TRIALS_M1*(1+TRIAL_GR)^(J$4-1),TRIAL_CAP) -> 79.800596 | K5: =MIN(TRIALS_M1*(1+TRIAL_GR)^(K$4-1),TRIAL_CAP) -> 91.770686 | ... Z5: =MIN(TRIALS_M1*(1+TRIAL_GR)^(Z$4-1),TRIAL_CAP) -> 500 | AA5: =SUM(C5:Z5) -> 5064.3036
B6: Новые платящие | C6: =C5*TRIAL_CONV+DIRECT_NEW -> 12.5 | D6: =D5*TRIAL_CONV+DIRECT_NEW -> 13.625 | E6: =E5*TRIAL_CONV+DIRECT_NEW -> 14.91875 | F6: =F5*TRIAL_CONV+DIRECT_NEW -> 16.406562 | G6: =G5*TRIAL_CONV+DIRECT_NEW -> 18.117547 | H6: =H5*TRIAL_CONV+DIRECT_NEW -> 20.085179 | I6: =I5*TRIAL_CONV+DIRECT_NEW -> 22.347956 | J6: =J5*TRIAL_CONV+DIRECT_NEW -> 24.950149 | ... Z6: =Z5*TRIAL_CONV+DIRECT_NEW -> 130 | AA6: =SUM(C6:Z6) -> 1386.0759
B7: Отток | C7: 0 | D7: =C8*CHURN -> 0.625 | E7: =D8*CHURN -> 1.275 | F7: =E8*CHURN -> 1.9571875 | G7: =F8*CHURN -> 2.6796563 | H7: =G8*CHURN -> 3.4515508 | I7: =H8*CHURN -> 4.2832322 | J7: =I8*CHURN -> 5.1864684 | K7: =J8*CHURN -> 6.1746524 | ... Z7: =Y8*CHURN -> 46.923959 | AA7: =SUM(C7:Z7) -> 364.52068
B8: Платящие (конец месяца) | C8: =C6 -> 12.5 | D8: =C8+D6-D7 -> 25.5 | E8: =D8+E6-E7 -> 39.14375 | F8: =E8+F6-F7 -> 53.593125 | G8: =F8+G6-G7 -> 69.031016 | H8: =G8+H6-H7 -> 85.664644 | I8: =H8+I6-I7 -> 103.72937 | J8: =I8+J6-J7 -> 123.49305 | K8: =J8+K6-K7 -> 145.26107 | ... Z8: =Y8+Z6-Z7 -> 1021.5552 | AA8: =Z8 -> 1021.5552
B9: в т.ч. подписка «Старт» | C9: =C8*SUB_START_SH -> 3.125 | D9: =D8*SUB_START_SH -> 6.375 | E9: =E8*SUB_START_SH -> 9.7859375 | F9: =F8*SUB_START_SH -> 13.398281 | G9: =G8*SUB_START_SH -> 17.257754 | H9: =H8*SUB_START_SH -> 21.416161 | I9: =I8*SUB_START_SH -> 25.932342 | J9: =J8*SUB_START_SH -> 30.873262 | ... Z9: =Z8*SUB_START_SH -> 255.38881 | AA9: =Z9 -> 255.38881
B10: в т.ч. подписка «Бизнес» | C10: =C8*SUB_BIZ_SH -> 1 | D10: =D8*SUB_BIZ_SH -> 2.04 | E10: =E8*SUB_BIZ_SH -> 3.1315 | F10: =F8*SUB_BIZ_SH -> 4.28745 | G10: =G8*SUB_BIZ_SH -> 5.5224813 | H10: =H8*SUB_BIZ_SH -> 6.8531715 | I10: =I8*SUB_BIZ_SH -> 8.2983494 | J10: =J8*SUB_BIZ_SH -> 9.8794438 | ... Z10: =Z8*SUB_BIZ_SH -> 81.724418 | AA10: =Z10 -> 81.724418
B11: в т.ч. разовые | C11: =C8*CASUAL_SH -> 8.375 | D11: =D8*CASUAL_SH -> 17.085 | E11: =E8*CASUAL_SH -> 26.226313 | F11: =F8*CASUAL_SH -> 35.907394 | G11: =G8*CASUAL_SH -> 46.25078 | H11: =H8*CASUAL_SH -> 57.395311 | I11: =I8*CASUAL_SH -> 69.498676 | J11: =J8*CASUAL_SH -> 82.740342 | ... Z11: =Z8*CASUAL_SH -> 684.442 | AA11: =Z11 -> 684.442
B12: Вакансий за месяц | C12: =C11*CASUAL_ACT*VAC_PER_EMP+C9*VAC_PER_EMP_SUB+C10*VAC_PER_EMP_BIZ -> 17.7875 | D12: =D11*CASUAL_ACT*VAC_PER_EMP+D9*VAC_PER_EMP_SUB+D10*VAC_PER_EMP_BIZ -> 36.2865 | E12: =E11*CASUAL_ACT*VAC_PER_EMP+E9*VAC_PER_EMP_SUB+E10*VAC_PER_EMP_BIZ -> 55.701556 | F12: =F11*CASUAL_ACT*VAC_PER_EMP+F9*VAC_PER_EMP_SUB+F10*VAC_PER_EMP_BIZ -> 76.263017 | G12: =G11*CASUAL_ACT*VAC_PER_EMP+G9*VAC_PER_EMP_SUB+G10*VAC_PER_EMP_BIZ -> 98.231135 | H12: =H11*CASUAL_ACT*VAC_PER_EMP+H9*VAC_PER_EMP_SUB+H10*VAC_PER_EMP_BIZ -> 121.90079 | I12: =I11*CASUAL_ACT*VAC_PER_EMP+I9*VAC_PER_EMP_SUB+I10*VAC_PER_EMP_BIZ -> 147.60689 | J12: =J11*CASUAL_ACT*VAC_PER_EMP+J9*VAC_PER_EMP_SUB+J10*VAC_PER_EMP_BIZ -> 175.73061 | ... Z12: =Z11*CASUAL_ACT*VAC_PER_EMP+Z9*VAC_PER_EMP_SUB+Z10*VAC_PER_EMP_BIZ -> 1453.6731 | AA12: =SUM(C12:Z12) -> 11827.932
B13: Приглашений за месяц | C13: =C11*CASUAL_ACT*INV_PER_EMP_CAS+C9*INV_PER_EMP_SUB+C10*INV_PER_EMP_BIZ -> 672.8 | D13: =D11*CASUAL_ACT*INV_PER_EMP_CAS+D9*INV_PER_EMP_SUB+D10*INV_PER_EMP_BIZ -> 1372.512 | E13: =E11*CASUAL_ACT*INV_PER_EMP_CAS+E9*INV_PER_EMP_SUB+E10*INV_PER_EMP_BIZ -> 2106.8732 | F13: =F11*CASUAL_ACT*INV_PER_EMP_CAS+F9*INV_PER_EMP_SUB+F10*INV_PER_EMP_BIZ -> 2884.5964 | G13: =G11*CASUAL_ACT*INV_PER_EMP_CAS+G9*INV_PER_EMP_SUB+G10*INV_PER_EMP_BIZ -> 3715.5254 | H13: =H11*CASUAL_ACT*INV_PER_EMP_CAS+H9*INV_PER_EMP_SUB+H10*INV_PER_EMP_BIZ -> 4610.8138 | I13: =I11*CASUAL_ACT*INV_PER_EMP_CAS+I9*INV_PER_EMP_SUB+I10*INV_PER_EMP_BIZ -> 5583.1295 | J13: =J11*CASUAL_ACT*INV_PER_EMP_CAS+J9*INV_PER_EMP_SUB+J10*INV_PER_EMP_BIZ -> 6646.8898 | ... Z13: =Z11*CASUAL_ACT*INV_PER_EMP_CAS+Z9*INV_PER_EMP_SUB+Z10*INV_PER_EMP_BIZ -> 54984.188 | AA13: =SUM(C13:Z13) -> 447383.41
B14: Выручка: подписки «Старт», ₽ | C14: =C9*SUB_START -> 30937.5 | D14: =D9*SUB_START -> 63112.5 | E14: =E9*SUB_START -> 96880.781 | F14: =F9*SUB_START -> 132642.98 | G14: =G9*SUB_START -> 170851.76 | H14: =H9*SUB_START -> 212019.99 | I14: =I9*SUB_START -> 256730.18 | J14: =J9*SUB_START -> 305645.29 | ... Z14: =Z9*SUB_START -> 2528349.2 | AA14: =SUM(C14:Z14) -> 20572123
B15: Выручка: подписки «Бизнес», ₽ | C15: =C10*SUB_BIZ -> 29900 | D15: =D10*SUB_BIZ -> 60996 | E15: =E10*SUB_BIZ -> 93631.85 | F15: =F10*SUB_BIZ -> 128194.75 | G15: =G10*SUB_BIZ -> 165122.19 | H15: =H10*SUB_BIZ -> 204909.83 | I15: =I10*SUB_BIZ -> 248120.65 | J15: =J10*SUB_BIZ -> 295395.37 | ... Z15: =Z10*SUB_BIZ -> 2443560.1 | AA15: =SUM(C15:Z15) -> 19882229
B16: Выручка: разовые, ₽ | C16: =C11*CASUAL_ACT*(VAC_PER_EMP*VAC_AVG+INV_PER_EMP_CAS*INV_PRICE) -> 6263.6625 | D16: =D11*CASUAL_ACT*(VAC_PER_EMP*VAC_AVG+INV_PER_EMP_CAS*INV_PRICE) -> 12777.871 | E16: =E11*CASUAL_ACT*(VAC_PER_EMP*VAC_AVG+INV_PER_EMP_CAS*INV_PRICE) -> 19614.659 | F16: =F11*CASUAL_ACT*(VAC_PER_EMP*VAC_AVG+INV_PER_EMP_CAS*INV_PRICE) -> 26855.14 | G16: =G11*CASUAL_ACT*(VAC_PER_EMP*VAC_AVG+INV_PER_EMP_CAS*INV_PRICE) -> 34590.959 | H16: =H11*CASUAL_ACT*(VAC_PER_EMP*VAC_AVG+INV_PER_EMP_CAS*INV_PRICE) -> 42925.953 | I16: =I11*CASUAL_ACT*(VAC_PER_EMP*VAC_AVG+INV_PER_EMP_CAS*INV_PRICE) -> 51978.06 | J16: =J11*CASUAL_ACT*(VAC_PER_EMP*VAC_AVG+INV_PER_EMP_CAS*INV_PRICE) -> 61881.502 | ... Z16: =Z11*CASUAL_ACT*(VAC_PER_EMP*VAC_AVG+INV_PER_EMP_CAS*INV_PRICE) -> 511894.17 | AA16: =SUM(C16:Z16) -> 4165069.4
B17: Выручка: штрафы SLA, ₽ | C17: =C12*FINE_SHARE*FINE -> 176.98563 | D17: =D12*FINE_SHARE*FINE -> 361.05068 | E17: =E12*FINE_SHARE*FINE -> 554.23048 | F17: =F12*FINE_SHARE*FINE -> 758.81702 | G17: =G12*FINE_SHARE*FINE -> 977.3998 | H17: =H12*FINE_SHARE*FINE -> 1212.9128 | I17: =I12*FINE_SHARE*FINE -> 1468.6886 | J17: =J12*FINE_SHARE*FINE -> 1748.5195 | ... Z17: =Z12*FINE_SHARE*FINE -> 14464.047 | AA17: =SUM(C17:Z17) -> 117687.92
B18: ИТОГО выручка, ₽ | C18: =SUM(C14:C17) -> 67278.148 | D18: =SUM(D14:D17) -> 137247.42 | E18: =SUM(E14:E17) -> 210681.52 | F18: =SUM(F14:F17) -> 288451.7 | G18: =SUM(G14:G17) -> 371542.31 | H18: =SUM(H14:H17) -> 461068.69 | I18: =SUM(I14:I17) -> 558297.58 | J18: =SUM(J14:J17) -> 664670.69 | ... Z18: =SUM(Z14:Z17) -> 5498267.5 | AA18: =SUM(C18:Z18) -> 44737109
B19: Накопленная выручка, ₽ | C19: =C18 -> 67278.148 | D19: =C19+D18 -> 204525.57 | E19: =D19+E18 -> 415207.09 | F19: =E19+F18 -> 703658.79 | G19: =F19+G18 -> 1075201.1 | H19: =G19+H18 -> 1536269.8 | I19: =H19+I18 -> 2094567.4 | J19: =I19+J18 -> 2759238.1 | K19: =J19+K18 -> 3541069.7 | ... Z19: =Y19+Z18 -> 44737109 | AA19: =Z19 -> 44737109
B22: Данные графика (значения из модели):
B23: Месяц | C23: Выручка, ₽ | D23: EBITDA, ₽
B24: 1 | C24: 67278 | D24: -712465
B25: 2 | C25: 137247 | D25: -654826
B26: 3 | C26: 210682 | D26: -595265
B27: 4 | C27: 288452 | D27: -533156
B28: 5 | C28: 371542 | D28: -467799
B29: 6 | C29: 461069 | D29: -398402
B30: 7 | C30: 558298 | D30: -874071
B31: 8 | C31: 664671 | D31: -793793
B32: 9 | C32: 781832 | D32: -706416
B33: 10 | C33: 911657 | D33: -610626
B34: 11 | C34: 1056292 | D34: -504929
B35: 12 | C35: 1218191 | D35: -387614
... B47: 24 | C47: 5498267 | D47: 2962758

Sheet Затраты
B2: Затраты COMIT — помесячная модель, 24 месяца
B4: Статья затрат | C4: 1 | D4: 2 | E4: 3 | F4: 4 | G4: 5 | H4: 6 | I4: 7 | J4: 8 | K4: 9 | L4: 10 | M4: 11 | N4: 12 | O4: 13 | P4: 14 | Q4: 15 | R4: 16 | S4: 17 | T4: 18 | U4: 19 | V4: 20 | W4: 21 | X4: 22 | Y4: 23 | Z4: 24 | AA4: Итого
B5: Вакансий (из «Выручка») | C5: =Выручка!C12 -> 17.7875 | D5: =Выручка!D12 -> 36.2865 | E5: =Выручка!E12 -> 55.701556 | F5: =Выручка!F12 -> 76.263017 | G5: =Выручка!G12 -> 98.231135 | H5: =Выручка!H12 -> 121.90079 | I5: =Выручка!I12 -> 147.60689 | J5: =Выручка!J12 -> 175.73061 | ... Z5: =Выручка!Z12 -> 1453.6731
B6: Приглашений (из «Выручка») | C6: =Выручка!C13 -> 672.8 | D6: =Выручка!D13 -> 1372.512 | E6: =Выручка!E13 -> 2106.8732 | F6: =Выручка!F13 -> 2884.5964 | G6: =Выручка!G13 -> 3715.5254 | H6: =Выручка!H13 -> 4610.8138 | I6: =Выручка!I13 -> 5583.1295 | J6: =Выручка!J13 -> 6646.8898 | ... Z6: =Выручка!Z13 -> 54984.188
B7: Чаты агентов | C7: =Выручка!C8*CHATS_PER_EMP -> 25 | D7: =Выручка!D8*CHATS_PER_EMP -> 51 | E7: =Выручка!E8*CHATS_PER_EMP -> 78.2875 | F7: =Выручка!F8*CHATS_PER_EMP -> 107.18625 | G7: =Выручка!G8*CHATS_PER_EMP -> 138.06203 | H7: =Выручка!H8*CHATS_PER_EMP -> 171.32929 | I7: =Выручка!I8*CHATS_PER_EMP -> 207.45873 | J7: =Выручка!J8*CHATS_PER_EMP -> 246.9861 | ... Z7: =Выручка!Z8*CHATS_PER_EMP -> 2043.1104
B8: LLM-затраты, ₽ | C8: =(C5*LLM_VAC+C6*LLM_INV+C7*LLM_CHAT)*LLM_BUF -> 309.15075 | D8: =(D5*LLM_VAC+D6*LLM_INV+D7*LLM_CHAT)*LLM_BUF -> 630.66753 | E8: =(E5*LLM_VAC+E6*LLM_INV+E7*LLM_CHAT)*LLM_BUF -> 968.10557 | F8: =(F5*LLM_VAC+F6*LLM_INV+F7*LLM_CHAT)*LLM_BUF -> 1325.4684 | G8: =(G5*LLM_VAC+G6*LLM_INV+G7*LLM_CHAT)*LLM_BUF -> 1707.2792 | H8: =(H5*LLM_VAC+H6*LLM_INV+H7*LLM_CHAT)*LLM_BUF -> 2118.6631 | I8: =(I5*LLM_VAC+I6*LLM_INV+I7*LLM_CHAT)*LLM_BUF -> 2565.4409 | J8: =(J5*LLM_VAC+J6*LLM_INV+J7*LLM_CHAT)*LLM_BUF -> 3054.2375 | ... Z8: =(Z5*LLM_VAC+Z6*LLM_INV+Z7*LLM_CHAT)*LLM_BUF -> 25265.165 | AA8: =SUM(C8:Z8) -> 205572.11
B9: Инфраструктура, ₽ | C9: =INFRA_FIX+INFRA_PER_EMP*(Выручка!C8+Выручка!C5) -> 27550 | D9: =INFRA_FIX+INFRA_PER_EMP*(Выручка!D8+Выручка!D5) -> 28600 | E9: =INFRA_FIX+INFRA_PER_EMP*(Выручка!E8+Выручка!E5) -> 29729.125 | F9: =INFRA_FIX+INFRA_PER_EMP*(Выручка!F8+Выручка!F5) -> 30953.162 | G9: =INFRA_FIX+INFRA_PER_EMP*(Выручка!G8+Выручка!G5) -> 32290.072 | H9: =INFRA_FIX+INFRA_PER_EMP*(Выручка!H8+Выручка!H5) -> 33760.322 | I9: =INFRA_FIX+INFRA_PER_EMP*(Выручка!I8+Выручка!I5) -> 35387.271 | J9: =INFRA_FIX+INFRA_PER_EMP*(Выручка!J8+Выручка!J5) -> 37197.619 | ... Z9: =INFRA_FIX+INFRA_PER_EMP*(Выручка!Z8+Выручка!Z5) -> 116293.31 | AA9: =SUM(C9:Z9) -> 1402576.3
B10: Маркетинг, ₽ | C10: =Выручка!C5*COST_TRIAL_MKT+DIRECT_NEW*CAC_DIRECT -> 110000 | D10: =Выручка!D5*COST_TRIAL_MKT+DIRECT_NEW*CAC_DIRECT -> 119000 | E10: =Выручка!E5*COST_TRIAL_MKT+DIRECT_NEW*CAC_DIRECT -> 129350 | F10: =Выручка!F5*COST_TRIAL_MKT+DIRECT_NEW*CAC_DIRECT -> 141252.5 | G10: =Выручка!G5*COST_TRIAL_MKT+DIRECT_NEW*CAC_DIRECT -> 154940.37 | H10: =Выручка!H5*COST_TRIAL_MKT+DIRECT_NEW*CAC_DIRECT -> 170681.43 | I10: =Выручка!I5*COST_TRIAL_MKT+DIRECT_NEW*CAC_DIRECT -> 188783.65 | J10: =Выручка!J5*COST_TRIAL_MKT+DIRECT_NEW*CAC_DIRECT -> 209601.19 | ... Z10: =Выручка!Z5*COST_TRIAL_MKT+DIRECT_NEW*CAC_DIRECT -> 1050000 | AA10: =SUM(C10:Z10) -> 11328607
B11: Эквайринг, ₽ | C11: =ACQ*Выручка!C18 -> 1883.7881 | D11: =ACQ*Выручка!D18 -> 3842.9278 | E11: =ACQ*Выручка!E18 -> 5899.0826 | F11: =ACQ*Выручка!F18 -> 8076.6475 | G11: =ACQ*Выручка!G18 -> 10403.185 | H11: =ACQ*Выручка!H18 -> 12909.923 | I11: =ACQ*Выручка!I18 -> 15632.332 | J11: =ACQ*Выручка!J18 -> 18610.779 | ... Z11: =ACQ*Выручка!Z18 -> 153951.49 | AA11: =SUM(C11:Z11) -> 1252639.1
B12: ФОТ + взносы, ₽ | C12: =IF(C$4<=6,PAYROLL_EARLY,PAYROLL_LATE) -> 600000 | D12: =IF(D$4<=6,PAYROLL_EARLY,PAYROLL_LATE) -> 600000 | E12: =IF(E$4<=6,PAYROLL_EARLY,PAYROLL_LATE) -> 600000 | F12: =IF(F$4<=6,PAYROLL_EARLY,PAYROLL_LATE) -> 600000 | G12: =IF(G$4<=6,PAYROLL_EARLY,PAYROLL_LATE) -> 600000 | H12: =IF(H$4<=6,PAYROLL_EARLY,PAYROLL_LATE) -> 600000 | I12: =IF(I$4<=6,PAYROLL_EARLY,PAYROLL_LATE) -> 1150000 | J12: =IF(J$4<=6,PAYROLL_EARLY,PAYROLL_LATE) -> 1150000 | ... Z12: =IF(Z$4<=6,PAYROLL_EARLY,PAYROLL_LATE) -> 1150000 | AA12: =SUM(C12:Z12) -> 24300000
B13: Прочие постоянные, ₽ | C13: =OPEX_OTHER -> 40000 | D13: =OPEX_OTHER -> 40000 | E13: =OPEX_OTHER -> 40000 | F13: =OPEX_OTHER -> 40000 | G13: =OPEX_OTHER -> 40000 | H13: =OPEX_OTHER -> 40000 | I13: =OPEX_OTHER -> 40000 | J13: =OPEX_OTHER -> 40000 | ... Z13: =OPEX_OTHER -> 40000 | AA13: =SUM(C13:Z13) -> 960000
B14: ИТОГО затрат, ₽ | C14: =SUM(C8:C13) -> 779742.94 | D14: =SUM(D8:D13) -> 792073.6 | E14: =SUM(E8:E13) -> 805946.31 | F14: =SUM(F8:F13) -> 821607.78 | G14: =SUM(G8:G13) -> 839340.91 | H14: =SUM(H8:H13) -> 859470.34 | I14: =SUM(I8:I13) -> 1432368.7 | J14: =SUM(J8:J13) -> 1458463.8 | ... Z14: =SUM(Z8:Z13) -> 2535510 | AA14: =SUM(C14:Z14) -> 39449395
B15: EBITDA, ₽ | C15: =Выручка!C18-C14 -> -712464.79 | D15: =Выручка!D18-D14 -> -654826.17 | E15: =Выручка!E18-E14 -> -595264.79 | F15: =Выручка!F18-F14 -> -533156.08 | G15: =Выручка!G18-G14 -> -467798.6 | H15: =Выручка!H18-H14 -> -398401.65 | I15: =Выручка!I18-I14 -> -874071.11 | J15: =Выручка!J18-J14 -> -793793.14 | ... Z15: =Выручка!Z18-Z14 -> 2962757.5 | AA15: =SUM(C15:Z15) -> 5287714.7
B16: Накопленный денежный поток, ₽ | C16: =C15 -> -712464.79 | D16: =C16+D15 -> -1367291 | E16: =D16+E15 -> -1962555.8 | F16: =E16+F15 -> -2495711.8 | G16: =F16+G15 -> -2963510.4 | H16: =G16+H15 -> -3361912.1 | I16: =H16+I15 -> -4235983.2 | J16: =I16+J15 -> -5029776.3 | K16: =J16+K15 -> -5736191.9 | ... Z16: =Y16+Z15 -> 5287714.7 | AA16: =Z16 -> 5287714.7
B18: Зелёный шрифт — ссылки на лист «Выручка». EBITDA здесь — до налогов и амортизации (стартап, УСН отложен).

Sheet Юнит-экономика
B2: Юнит-экономика платящего работодателя
B4: Показатель | C4: Значение | D4: Как считаем
B5: ARPU (стабилизированный микс), ₽/мес | C5: =CASUAL_SH*CASUAL_ACT*(VAC_PER_EMP*VAC_AVG+INV_PER_EMP_CAS*INV_PRICE)+SUB_START_SH*SUB_START+SUB_BIZ_SH*SUB_BIZ -> 5368.093 | D5: доли × средняя выручка тарифа на работодателя
B6: Вакансий на платящего, мес | C6: =CASUAL_SH*CASUAL_ACT*VAC_PER_EMP+SUB_START_SH*VAC_PER_EMP_SUB+SUB_BIZ_SH*VAC_PER_EMP_BIZ -> 1.423 | D6: для LLM-затрат
B7: Приглашений на платящего, мес | C7: =CASUAL_SH*CASUAL_ACT*INV_PER_EMP_CAS+SUB_START_SH*INV_PER_EMP_SUB+SUB_BIZ_SH*INV_PER_EMP_BIZ -> 53.824 | D7: для LLM-затрат
B8: LLM-затраты на работодателя, ₽/мес | C8: =(C6*LLM_VAC+C7*LLM_INV+CHATS_PER_EMP*LLM_CHAT)*LLM_BUF -> 24.73206 | D8: DeepSeek по тарифам из «Допущений»
B9: Переменные затраты на работодателя, ₽/мес | C9: =INFRA_PER_EMP+C8+ACQ*C5 -> 235.03866 | D9: инфраструктура + LLM + эквайринг
B10: Маржинальная прибыль на работодателя, ₽/мес | C10: =C5-C9 -> 5133.0543 | D10: ARPU − переменные
B11: Валовая маржа, % | C11: =IF(C5=0,0,C10/C5) -> 0.95621561 | D11: маржинальная прибыль / ARPU
B12: Отток в месяц | C12: =CHURN -> 0.05 | D12: допущение
B13: Средняя жизнь клиента, мес | C13: =IF(CHURN=0,0,1/CHURN) -> 20 | D13: 1 / отток
B14: LTV, ₽ | C14: =C10*C13 -> 102661.09 | D14: маржинальная прибыль × жизнь
B15: CAC (смешанный, мес 7–12), ₽ | C15: =AVERAGE(Затраты!I10:N10)/AVERAGE(Выручка!I6:N6) -> 8329.9251 | D15: средний маркетинг / средние новые платящие
B16: LTV / CAC | C16: =IF(C15=0,0,C14/C15) -> 12.324371 | D16: здоровая экономика: > 3×
B17: Окупаемость CAC, мес | C17: =IF(C10=0,0,C15/C10) -> 1.6228009 | D17: CAC / маржинальная прибыль
B18: ARR на одного платящего, ₽/год | C18: =C5*12 -> 64417.116 | D18: ARPU × 12

Sheet Безубыточность
B2: Точка безубыточности
B4: Показатель | C4: Значение | D4: Как считаем
B5: Постоянные затраты (мес 7–24), ₽/мес | C5: =PAYROLL_LATE+INFRA_FIX+OPEX_OTHER -> 1215000 | D5: ФОТ 5 чел. + инфраструктура-фикс + прочие (маркетинг — переменный, в CAC)
B6: Маржинальная прибыль на работодателя, ₽/мес | C6: ='Юнит-экономика'!C10 -> 5133.0543 | D6: из юнит-экономики
B7: Точка безубыточности, платящих работодателей | C7: =ROUNDUP(C5/C6+0.001,0) -> 237 | D7: постоянные / маржинальная прибыль
B8: Месяц выхода EBITDA в плюс | C8: =IF(COUNTIF(Затраты!C15:Z15,"<=0")>=24,"не достигается",COUNTIF(Затраты!C15:Z15,"<=0")+1) -> 15 | D8: первый месяц с EBITDA > 0 по помесячной модели
B9: Платящих на конец мес 24 (база) | C9: =Выручка!Z8 -> 1021.5552 | D9: из модели выручки
B10: Максимальная потребность в деньгах (кумулятивный минимум), ₽ | C10: =MIN(Затраты!C16:Z16) -> -7606118.2 | D10: глубина кассового разрыва до выхода в плюс
B13: Данные графика (значения из модели):
B14: Месяц | C14: Выручка, ₽ | D14: Затраты, ₽
B15: 1 | C15: 67278 | D15: 779743
B16: 2 | C16: 137247 | D16: 792074
B17: 3 | C17: 210682 | D17: 805946
B18: 4 | C18: 288452 | D18: 821608
B19: 5 | C19: 371542 | D19: 839341
B20: 6 | C20: 461069 | D20: 859470
B21: 7 | C21: 558298 | D21: 1432369
B22: 8 | C22: 664671 | D22: 1458464
B23: 9 | C23: 781832 | D23: 1488247
B24: 10 | C24: 911657 | D24: 1522283
B25: 11 | C25: 1056292 | D25: 1561221
B26: 12 | C26: 1218191 | D26: 1605805
... B38: 24 | C38: 5498267 | D38: 2535510

Sheet Сценарии
B2: Сценарии и чувствительность
B4: Параметры сценариев (меняются вручную)
B5: Драйвер | C5: Пессимистичный | D5: Базовый | E5: Оптимистичный
B6: Рост триалов в месяц | C6: 0.08 | D6: 0.15 | E6: 0.22
B7: Конверсия триал → платящий | C7: 0.15 | D7: 0.25 | E7: 0.35
B8: Отток платящих в месяц | C8: 0.08 | D8: 0.05 | E8: 0.035
B9: Стоимость привлечения триала, ₽ | C9: 3000 | D9: 2000 | E9: 1500
B11: Результаты сценариев (мес 24)
B12: Показатель | C12: Пессимистичный | D12: Базовый | E12: Оптимистичный
B13: Платящих работодателей на мес 24 | C13: =SUMPRODUCT((TRIALS_M1*C7*(1+C6)^(ROW(INDIRECT("1:24"))-1)+DIRECT_NEW)*(1-C8)^(24-ROW(INDIRECT("1:24")))) -> 228.59515 | D13: =SUMPRODUCT((TRIALS_M1*D7*(1+D6)^(ROW(INDIRECT("1:24"))-1)+DIRECT_NEW)*(1-D8)^(24-ROW(INDIRECT("1:24")))) -> 1133.2956 | E13: =SUMPRODUCT((TRIALS_M1*E7*(1+E6)^(ROW(INDIRECT("1:24"))-1)+DIRECT_NEW)*(1-E8)^(24-ROW(INDIRECT("1:24")))) -> 4931.8605
B14: Выручка в месяц 24, ₽ | C14: =SUMPRODUCT((TRIALS_M1*C7*(1+C6)^(ROW(INDIRECT("1:24"))-1)+DIRECT_NEW)*(1-C8)^(24-ROW(INDIRECT("1:24"))))*'Юнит-экономика'!$C$5 -> 1227120 | D14: =SUMPRODUCT((TRIALS_M1*D7*(1+D6)^(ROW(INDIRECT("1:24"))-1)+DIRECT_NEW)*(1-D8)^(24-ROW(INDIRECT("1:24"))))*'Юнит-экономика'!$C$5 -> 6083636.3 | E14: =SUMPRODUCT((TRIALS_M1*E7*(1+E6)^(ROW(INDIRECT("1:24"))-1)+DIRECT_NEW)*(1-E8)^(24-ROW(INDIRECT("1:24"))))*'Юнит-экономика'!$C$5 -> 26474686
B15: ARR (годовая run-rate), ₽ | C15: =SUMPRODUCT((TRIALS_M1*C7*(1+C6)^(ROW(INDIRECT("1:24"))-1)+DIRECT_NEW)*(1-C8)^(24-ROW(INDIRECT("1:24"))))*'Юнит-экономика'!$C$5*12 -> 14725440 | D15: =SUMPRODUCT((TRIALS_M1*D7*(1+D6)^(ROW(INDIRECT("1:24"))-1)+DIRECT_NEW)*(1-D8)^(24-ROW(INDIRECT("1:24"))))*'Юнит-экономика'!$C$5*12 -> 73003635 | E15: =SUMPRODUCT((TRIALS_M1*E7*(1+E6)^(ROW(INDIRECT("1:24"))-1)+DIRECT_NEW)*(1-E8)^(24-ROW(INDIRECT("1:24"))))*'Юнит-экономика'!$C$5*12 -> 3.1769623e+08
B16: CAC при сценарии, ₽ | C16: =(C9+(LLM_VAC+10*LLM_INV+2*LLM_CHAT)*LLM_BUF+SUPPORT_TRIAL+INFRA_PER_EMP)/C7 -> 21781.733 | D16: =(D9+(LLM_VAC+10*LLM_INV+2*LLM_CHAT)*LLM_BUF+SUPPORT_TRIAL+INFRA_PER_EMP)/D7 -> 9069.04 | E16: =(E9+(LLM_VAC+10*LLM_INV+2*LLM_CHAT)*LLM_BUF+SUPPORT_TRIAL+INFRA_PER_EMP)/E7 -> 5049.3143
B17: LTV / CAC | C17: ='Юнит-экономика'!$C$14/C16 -> 4.7131734 | D17: ='Юнит-экономика'!$C$14/D16 -> 11.319951 | E17: ='Юнит-экономика'!$C$14/E16 -> 20.331689
B19: Чувствительность: ARR мес 24 (млрд ₽) — рост триалов × конверсия
B20: Рост \ Конверсия | C20: 0.15 | D20: 0.2 | E20: 0.25 | F20: 0.3 | G20: 0.35
B21: 0.08 | C21: =SUMPRODUCT((TRIALS_M1*C$20*(1+$B21)^(ROW(INDIRECT("1:24"))-1)+DIRECT_NEW)*(1-CHURN)^(24-ROW(INDIRECT("1:24"))))*'Юнит-экономика'!$C$5*12/1000000000 -> 0.018049431 | D21: =SUMPRODUCT((TRIALS_M1*D$20*(1+$B21)^(ROW(INDIRECT("1:24"))-1)+DIRECT_NEW)*(1-CHURN)^(24-ROW(INDIRECT("1:24"))))*'Юнит-экономика'!$C$5*12/1000000000 -> 0.02254564 | E21: =SUMPRODUCT((TRIALS_M1*E$20*(1+$B21)^(ROW(INDIRECT("1:24"))-1)+DIRECT_NEW)*(1-CHURN)^(24-ROW(INDIRECT("1:24"))))*'Юнит-экономика'!$C$5*12/1000000000 -> 0.02704185 | F21: =SUMPRODUCT((TRIALS_M1*F$20*(1+$B21)^(ROW(INDIRECT("1:24"))-1)+DIRECT_NEW)*(1-CHURN)^(24-ROW(INDIRECT("1:24"))))*'Юнит-экономика'!$C$5*12/1000000000 -> 0.031538059 | G21: =SUMPRODUCT((TRIALS_M1*G$20*(1+$B21)^(ROW(INDIRECT("1:24"))-1)+DIRECT_NEW)*(1-CHURN)^(24-ROW(INDIRECT("1:24"))))*'Юнит-экономика'!$C$5*12/1000000000 -> 0.036034269
B22: 0.12 | C22: =SUMPRODUCT((TRIALS_M1*C$20*(1+$B22)^(ROW(INDIRECT("1:24"))-1)+DIRECT_NEW)*(1-CHURN)^(24-ROW(INDIRECT("1:24"))))*'Юнит-экономика'!$C$5*12/1000000000 -> 0.02994489 | D22: =SUMPRODUCT((TRIALS_M1*D$20*(1+$B22)^(ROW(INDIRECT("1:24"))-1)+DIRECT_NEW)*(1-CHURN)^(24-ROW(INDIRECT("1:24"))))*'Юнит-экономика'!$C$5*12/1000000000 -> 0.038406252 | E22: =SUMPRODUCT((TRIALS_M1*E$20*(1+$B22)^(ROW(INDIRECT("1:24"))-1)+DIRECT_NEW)*(1-CHURN)^(24-ROW(INDIRECT("1:24"))))*'Юнит-экономика'!$C$5*12/1000000000 -> 0.046867615 | F22: =SUMPRODUCT((TRIALS_M1*F$20*(1+$B22)^(ROW(INDIRECT("1:24"))-1)+DIRECT_NEW)*(1-CHURN)^(24-ROW(INDIRECT("1:24"))))*'Юнит-экономика'!$C$5*12/1000000000 -> 0.055328977 | G22: =SUMPRODUCT((TRIALS_M1*G$20*(1+$B22)^(ROW(INDIRECT("1:24"))-1)+DIRECT_NEW)*(1-CHURN)^(24-ROW(INDIRECT("1:24"))))*'Юнит-экономика'!$C$5*12/1000000000 -> 0.06379034
B23: 0.15 | C23: =SUMPRODUCT((TRIALS_M1*C$20*(1+$B23)^(ROW(INDIRECT("1:24"))-1)+DIRECT_NEW)*(1-CHURN)^(24-ROW(INDIRECT("1:24"))))*'Юнит-экономика'!$C$5*12/1000000000 -> 0.045626502 | D23: =SUMPRODUCT((TRIALS_M1*D$20*(1+$B23)^(ROW(INDIRECT("1:24"))-1)+DIRECT_NEW)*(1-CHURN)^(24-ROW(INDIRECT("1:24"))))*'Юнит-экономика'!$C$5*12/1000000000 -> 0.059315069 | E23: =SUMPRODUCT((TRIALS_M1*E$20*(1+$B23)^(ROW(INDIRECT("1:24"))-1)+DIRECT_NEW)*(1-CHURN)^(24-ROW(INDIRECT("1:24"))))*'Юнит-экономика'!$C$5*12/1000000000 -> 0.073003635 | F23: =SUMPRODUCT((TRIALS_M1*F$20*(1+$B23)^(ROW(INDIRECT("1:24"))-1)+DIRECT_NEW)*(1-CHURN)^(24-ROW(INDIRECT("1:24"))))*'Юнит-экономика'!$C$5*12/1000000000 -> 0.086692202 | G23: =SUMPRODUCT((TRIALS_M1*G$20*(1+$B23)^(ROW(INDIRECT("1:24"))-1)+DIRECT_NEW)*(1-CHURN)^(24-ROW(INDIRECT("1:24"))))*'Юнит-экономика'!$C$5*12/1000000000 -> 0.10038077
B24: 0.18 | C24: =SUMPRODUCT((TRIALS_M1*C$20*(1+$B24)^(ROW(INDIRECT("1:24"))-1)+DIRECT_NEW)*(1-CHURN)^(24-ROW(INDIRECT("1:24"))))*'Юнит-экономика'!$C$5*12/1000000000 -> 0.071127932 | D24: =SUMPRODUCT((TRIALS_M1*D$20*(1+$B24)^(ROW(INDIRECT("1:24"))-1)+DIRECT_NEW)*(1-CHURN)^(24-ROW(INDIRECT("1:24"))))*'Юнит-экономика'!$C$5*12/1000000000 -> 0.093316975 | E24: =SUMPRODUCT((TRIALS_M1*E$20*(1+$B24)^(ROW(INDIRECT("1:24"))-1)+DIRECT_NEW)*(1-CHURN)^(24-ROW(INDIRECT("1:24"))))*'Юнит-экономика'!$C$5*12/1000000000 -> 0.11550602 | F24: =SUMPRODUCT((TRIALS_M1*F$20*(1+$B24)^(ROW(INDIRECT("1:24"))-1)+DIRECT_NEW)*(1-CHURN)^(24-ROW(INDIRECT("1:24"))))*'Юнит-экономика'!$C$5*12/1000000000 -> 0.13769506 | G24: =SUMPRODUCT((TRIALS_M1*G$20*(1+$B24)^(ROW(INDIRECT("1:24"))-1)+DIRECT_NEW)*(1-CHURN)^(24-ROW(INDIRECT("1:24"))))*'Юнит-экономика'!$C$5*12/1000000000 -> 0.1598841
B25: 0.22 | C25: =SUMPRODUCT((TRIALS_M1*C$20*(1+$B25)^(ROW(INDIRECT("1:24"))-1)+DIRECT_NEW)*(1-CHURN)^(24-ROW(INDIRECT("1:24"))))*'Юнит-экономика'!$C$5*12/1000000000 -> 0.13115443 | D25: =SUMPRODUCT((TRIALS_M1*D$20*(1+$B25)^(ROW(INDIRECT("1:24"))-1)+DIRECT_NEW)*(1-CHURN)^(24-ROW(INDIRECT("1:24"))))*'Юнит-экономика'!$C$5*12/1000000000 -> 0.17335231 | E25: =SUMPRODUCT((TRIALS_M1*E$20*(1+$B25)^(ROW(INDIRECT("1:24"))-1)+DIRECT_NEW)*(1-CHURN)^(24-ROW(INDIRECT("1:24"))))*'Юнит-экономика'!$C$5*12/1000000000 -> 0.21555018 | F25: =SUMPRODUCT((TRIALS_M1*F$20*(1+$B25)^(ROW(INDIRECT("1:24"))-1)+DIRECT_NEW)*(1-CHURN)^(24-ROW(INDIRECT("1:24"))))*'Юнит-экономика'!$C$5*12/1000000000 -> 0.25774806 | G25: =SUMPRODUCT((TRIALS_M1*G$20*(1+$B25)^(ROW(INDIRECT("1:24"))-1)+DIRECT_NEW)*(1-CHURN)^(24-ROW(INDIRECT("1:24"))))*'Юнит-экономика'!$C$5*12/1000000000 -> 0.29994593
B27: Примечание: формулы сценариев не учитывают потолок 500 триалов/мес — оптимистичный случай ограничен им (см. лист «Выручка», строка «Новые триалы»).

Sheet Источники
B2: Источники данных (проверены 11.10.2026)
B4: Данные | C4: Источник | D4: URL
B5: Медиана ЗП IT 182 700 ₽/мес (1П2025); Backend 251 тыс (2026) | C5: Хабр Карьера | D5: https://career.habr.com
B6: ЗП по грейдам: джун 77 / мидл 167 / синьор 280 тыс ₽ | C6: Skillbox (авг 2025) | D6: https://blog.skillbox.ru
B7: Средняя ЗП IT 196,5 тыс ₽ (3 кв 2025) | C7: TAdviser | D7: https://www.tadviser.ru
B8: Комиссия агентств 10–25% годового дохода | C8: IT-Atlas (май 2025) | D8: https://it-atlas.ru
B9: IT-агентства 19–23% | C9: Lucky Hunter | D9: https://luckyhunter.io
B10: Полный cost-per-hire > 43 000 ₽ на закрытую вакансию | C10: vc.ru | D10: https://vc.ru
B11: Доступ к базе hh.ru: 22 080 ₽/7 дней (Москва), 27 670 ₽ (РФ) | C11: heaad.ru | D11: https://heaad.ru
B12: Пакет hh: 6 200 ₽ за 10 вакансий; промо «Вакансия за 199 ₽» | C12: jcat.ru; hh.ru | D12: https://www.jcat.ru
B13: Хабр Карьера: Стандарт 4 026 ₽, «Стандарт плюс» 7 808 ₽, продвижение 1 220 ₽; модель 0 ₽ + 300 ₽/отклик (2025) | C13: career.habr.com/price; habr.com | D13: https://career.habr.com/price
B14: Выручка hh.ru 41,2 млрд ₽ (2025), прибыль 18,18 млрд ₽; рынок РФ > 500 млрд ₽ (TAM) | C14: TAdviser, Ведомости, investor.hh.ru | D14: https://investor.hh.ru
B15: IT-вакансии 1П2025: 352,5 → 291 тыс (−17%) | C15: proglib.io | D15: https://proglib.io
... B20: Ставки 199 ₽ / 49 ₽ / 199 ₽; курс 100 ₽/$; тарифы DeepSeek по умолчанию | C20: репозиторий comit_2 (context/80-open-questions.md, .env.example) | D20: https://github.com/mgg789/comit_2

Sheet Проверка
B2: Проверка модели (кросс-чеки)
B4: Проверка | C4: Ожидание | D4: Факт | E4: Статус
B5: Итого выручка мес 24 = сумма компонент | C5: =SUM(Выручка!Z14:Z17) -> 5498267.5 | D5: =Выручка!Z18 -> 5498267.5 | E5: =IF(ABS(C5-D5)<1,"OK","FAIL") -> OK
B6: Платящие мес 24: база + новые − отток | C6: =Выручка!Y8+Выручка!Z6-Выручка!Z7 -> 1021.5552 | D6: =Выручка!Z8 -> 1021.5552 | E6: =IF(ABS(C6-D6)<1,"OK","FAIL") -> OK
B7: Итого затрат мес 24 = сумма статей | C7: =SUM(Затраты!Z8:Z13) -> 2535510 | D7: =Затраты!Z14 -> 2535510 | E7: =IF(ABS(C7-D7)<1,"OK","FAIL") -> OK
B8: EBITDA мес 24 = выручка − затраты | C8: =Выручка!Z18-Затраты!Z14 -> 2962757.5 | D8: =Затраты!Z15 -> 2962757.5 | E8: =IF(ABS(C8-D8)<1,"OK","FAIL") -> OK
B9: ARPU × платящие мес 24 ≈ выручка мес 24 (±15%) | C9: ='Юнит-экономика'!C5*Выручка!Z8 -> 5483803.4 | D9: =Выручка!Z18 -> 5498267.5 | E9: =IF(ABS(C9-D9)<=0.15*ABS(D9),"OK","FAIL") -> OK
B10: Экономия против агентства = разница каналов | C10: ='Затраты работодателя'!F9-'Затраты работодателя'!F5 -> 444399 | D10: ='Затраты работодателя'!F13 -> 444399 | E10: =IF(ABS(C10-D10)<1,"OK","FAIL") -> OK
